[2023-11-02T08:32:53.226+0000] {taskinstance.py:1165} INFO - Dependencies all met for <TaskInstance: people_processing.create_table manual__2023-11-02T08:32:51.130489+00:00 [queued]>
[2023-11-02T08:32:53.241+0000] {taskinstance.py:1165} INFO - Dependencies all met for <TaskInstance: people_processing.create_table manual__2023-11-02T08:32:51.130489+00:00 [queued]>
[2023-11-02T08:32:53.242+0000] {taskinstance.py:1362} INFO - 
--------------------------------------------------------------------------------
[2023-11-02T08:32:53.243+0000] {taskinstance.py:1363} INFO - Starting attempt 1 of 1
[2023-11-02T08:32:53.244+0000] {taskinstance.py:1364} INFO - 
--------------------------------------------------------------------------------
[2023-11-02T08:32:53.266+0000] {taskinstance.py:1383} INFO - Executing <Task(PostgresOperator): create_table> on 2023-11-02 08:32:51.130489+00:00
[2023-11-02T08:32:53.272+0000] {standard_task_runner.py:55} INFO - Started process 3302 to run task
[2023-11-02T08:32:53.277+0000] {standard_task_runner.py:82} INFO - Running: ['***', 'tasks', 'run', 'people_processing', 'create_table', 'manual__2023-11-02T08:32:51.130489+00:00', '--job-id', '4', '--raw', '--subdir', 'DAGS_FOLDER/people.py', '--cfg-path', '/tmp/tmppglnme6j']
[2023-11-02T08:32:53.279+0000] {standard_task_runner.py:83} INFO - Job 4: Subtask create_table
[2023-11-02T08:32:53.361+0000] {task_command.py:376} INFO - Running <TaskInstance: people_processing.create_table manual__2023-11-02T08:32:51.130489+00:00 [running]> on host b33dd0bd4b35
[2023-11-02T08:32:53.467+0000] {taskinstance.py:1592} INFO - Exporting the following env vars:
AIRFLOW_CTX_DAG_OWNER=***
AIRFLOW_CTX_DAG_ID=people_processing
AIRFLOW_CTX_TASK_ID=create_table
AIRFLOW_CTX_EXECUTION_DATE=2023-11-02T08:32:51.130489+00:00
AIRFLOW_CTX_TRY_NUMBER=1
AIRFLOW_CTX_DAG_RUN_ID=manual__2023-11-02T08:32:51.130489+00:00
[2023-11-02T08:32:53.484+0000] {base.py:71} INFO - Using connection ID 'postgres' for task execution.
[2023-11-02T08:32:53.486+0000] {taskinstance.py:1851} ERROR - Task failed with exception
Traceback (most recent call last):
  File "/home/airflow/.local/lib/python3.7/site-packages/airflow/providers/postgres/operators/postgres.py", line 94, in execute
    self.hook.run(self.sql, self.autocommit, parameters=self.parameters)
  File "/home/airflow/.local/lib/python3.7/site-packages/airflow/providers/common/sql/hooks/sql.py", line 288, in run
    with closing(self.get_conn()) as conn:
  File "/home/airflow/.local/lib/python3.7/site-packages/airflow/providers/postgres/hooks/postgres.py", line 115, in get_conn
    self.conn = psycopg2.connect(**conn_args)
  File "/home/airflow/.local/lib/python3.7/site-packages/psycopg2/__init__.py", line 122, in connect
    conn = _connect(dsn, connection_factory=connection_factory, **kwasync)
psycopg2.OperationalError: connection to server on socket "/var/run/postgresql/.s.PGSQL.5433" failed: No such file or directory
	Is the server running locally and accepting connections on that socket?

[2023-11-02T08:32:53.497+0000] {taskinstance.py:1406} INFO - Marking task as FAILED. dag_id=people_processing, task_id=create_table, execution_date=20231102T083251, start_date=20231102T083253, end_date=20231102T083253
[2023-11-02T08:32:53.527+0000] {standard_task_runner.py:105} ERROR - Failed to execute job 4 for task create_table (connection to server on socket "/var/run/postgresql/.s.PGSQL.5433" failed: No such file or directory
	Is the server running locally and accepting connections on that socket?
; 3302)
[2023-11-02T08:32:53.573+0000] {local_task_job.py:164} INFO - Task exited with return code 1
[2023-11-02T08:32:53.605+0000] {local_task_job.py:273} INFO - 0 downstream tasks scheduled from follow-on schedule check
