[2023-11-02T10:46:44.419+0000] {taskinstance.py:1165} INFO - Dependencies all met for <TaskInstance: test_dag_tutorial.create_postgres_table scheduled__2020-01-30T00:00:00+00:00 [queued]>
[2023-11-02T10:46:44.489+0000] {taskinstance.py:1165} INFO - Dependencies all met for <TaskInstance: test_dag_tutorial.create_postgres_table scheduled__2020-01-30T00:00:00+00:00 [queued]>
[2023-11-02T10:46:44.490+0000] {taskinstance.py:1362} INFO - 
--------------------------------------------------------------------------------
[2023-11-02T10:46:44.492+0000] {taskinstance.py:1363} INFO - Starting attempt 1 of 6
[2023-11-02T10:46:44.495+0000] {taskinstance.py:1364} INFO - 
--------------------------------------------------------------------------------
[2023-11-02T10:46:44.702+0000] {taskinstance.py:1383} INFO - Executing <Task(PostgresOperator): create_postgres_table> on 2020-01-30 00:00:00+00:00
[2023-11-02T10:46:44.751+0000] {standard_task_runner.py:82} INFO - Running: ['***', 'tasks', 'run', 'test_dag_tutorial', 'create_postgres_table', 'scheduled__2020-01-30T00:00:00+00:00', '--job-id', '211', '--raw', '--subdir', 'DAGS_FOLDER/test_dag_tutorial.py', '--cfg-path', '/tmp/tmpohafrop0']
[2023-11-02T10:46:44.755+0000] {standard_task_runner.py:83} INFO - Job 211: Subtask create_postgres_table
[2023-11-02T10:46:44.755+0000] {standard_task_runner.py:55} INFO - Started process 1002 to run task
[2023-11-02T10:46:45.003+0000] {task_command.py:376} INFO - Running <TaskInstance: test_dag_tutorial.create_postgres_table scheduled__2020-01-30T00:00:00+00:00 [running]> on host 1dfdc0df4852
[2023-11-02T10:46:45.289+0000] {taskinstance.py:1592} INFO - Exporting the following env vars:
AIRFLOW_CTX_DAG_OWNER=tetiana
AIRFLOW_CTX_DAG_ID=test_dag_tutorial
AIRFLOW_CTX_TASK_ID=create_postgres_table
AIRFLOW_CTX_EXECUTION_DATE=2020-01-30T00:00:00+00:00
AIRFLOW_CTX_TRY_NUMBER=1
AIRFLOW_CTX_DAG_RUN_ID=scheduled__2020-01-30T00:00:00+00:00
[2023-11-02T10:46:45.325+0000] {base.py:71} INFO - Using connection ID 'postgres_localhost' for task execution.
[2023-11-02T10:46:45.327+0000] {taskinstance.py:1851} ERROR - Task failed with exception
Traceback (most recent call last):
  File "/home/airflow/.local/lib/python3.7/site-packages/airflow/providers/postgres/operators/postgres.py", line 94, in execute
    self.hook.run(self.sql, self.autocommit, parameters=self.parameters)
  File "/home/airflow/.local/lib/python3.7/site-packages/airflow/providers/common/sql/hooks/sql.py", line 288, in run
    with closing(self.get_conn()) as conn:
  File "/home/airflow/.local/lib/python3.7/site-packages/airflow/providers/postgres/hooks/postgres.py", line 115, in get_conn
    self.conn = psycopg2.connect(**conn_args)
  File "/home/airflow/.local/lib/python3.7/site-packages/psycopg2/__init__.py", line 122, in connect
    conn = _connect(dsn, connection_factory=connection_factory, **kwasync)
psycopg2.OperationalError: connection to server at "localhost" (127.0.0.1), port 5432 failed: Connection refused
	Is the server running on that host and accepting TCP/IP connections?
connection to server at "localhost" (::1), port 5432 failed: Cannot assign requested address
	Is the server running on that host and accepting TCP/IP connections?

[2023-11-02T10:46:45.346+0000] {taskinstance.py:1406} INFO - Marking task as UP_FOR_RETRY. dag_id=test_dag_tutorial, task_id=create_postgres_table, execution_date=20200130T000000, start_date=20231102T104644, end_date=20231102T104645
[2023-11-02T10:46:45.429+0000] {standard_task_runner.py:105} ERROR - Failed to execute job 211 for task create_postgres_table (connection to server at "localhost" (127.0.0.1), port 5432 failed: Connection refused
	Is the server running on that host and accepting TCP/IP connections?
connection to server at "localhost" (::1), port 5432 failed: Cannot assign requested address
	Is the server running on that host and accepting TCP/IP connections?
; 1002)
[2023-11-02T10:46:45.475+0000] {local_task_job.py:164} INFO - Task exited with return code 1
[2023-11-02T10:46:45.516+0000] {local_task_job.py:273} INFO - 0 downstream tasks scheduled from follow-on schedule check
[2023-11-02T10:55:33.967+0000] {taskinstance.py:1165} INFO - Dependencies all met for <TaskInstance: test_dag_tutorial.create_postgres_table scheduled__2020-01-30T00:00:00+00:00 [queued]>
[2023-11-02T10:55:33.992+0000] {taskinstance.py:1165} INFO - Dependencies all met for <TaskInstance: test_dag_tutorial.create_postgres_table scheduled__2020-01-30T00:00:00+00:00 [queued]>
[2023-11-02T10:55:33.993+0000] {taskinstance.py:1362} INFO - 
--------------------------------------------------------------------------------
[2023-11-02T10:55:33.993+0000] {taskinstance.py:1363} INFO - Starting attempt 1 of 1
[2023-11-02T10:55:33.994+0000] {taskinstance.py:1364} INFO - 
--------------------------------------------------------------------------------
[2023-11-02T10:55:34.073+0000] {taskinstance.py:1383} INFO - Executing <Task(PostgresOperator): create_postgres_table> on 2020-01-30 00:00:00+00:00
[2023-11-02T10:55:34.096+0000] {standard_task_runner.py:55} INFO - Started process 1458 to run task
[2023-11-02T10:55:34.116+0000] {standard_task_runner.py:82} INFO - Running: ['***', 'tasks', 'run', 'test_dag_tutorial', 'create_postgres_table', 'scheduled__2020-01-30T00:00:00+00:00', '--job-id', '244', '--raw', '--subdir', 'DAGS_FOLDER/test_dag_tutorial.py', '--cfg-path', '/tmp/tmpgkhlm1xl']
[2023-11-02T10:55:34.117+0000] {standard_task_runner.py:83} INFO - Job 244: Subtask create_postgres_table
[2023-11-02T10:55:34.414+0000] {task_command.py:376} INFO - Running <TaskInstance: test_dag_tutorial.create_postgres_table scheduled__2020-01-30T00:00:00+00:00 [running]> on host 1dfdc0df4852
[2023-11-02T10:55:35.000+0000] {taskinstance.py:1592} INFO - Exporting the following env vars:
AIRFLOW_CTX_DAG_OWNER=tetiana
AIRFLOW_CTX_DAG_ID=test_dag_tutorial
AIRFLOW_CTX_TASK_ID=create_postgres_table
AIRFLOW_CTX_EXECUTION_DATE=2020-01-30T00:00:00+00:00
AIRFLOW_CTX_TRY_NUMBER=1
AIRFLOW_CTX_DAG_RUN_ID=scheduled__2020-01-30T00:00:00+00:00
[2023-11-02T10:55:35.038+0000] {base.py:71} INFO - Using connection ID 'postgres_localhost' for task execution.
[2023-11-02T10:55:35.043+0000] {taskinstance.py:1851} ERROR - Task failed with exception
Traceback (most recent call last):
  File "/home/airflow/.local/lib/python3.7/site-packages/airflow/providers/postgres/operators/postgres.py", line 94, in execute
    self.hook.run(self.sql, self.autocommit, parameters=self.parameters)
  File "/home/airflow/.local/lib/python3.7/site-packages/airflow/providers/common/sql/hooks/sql.py", line 288, in run
    with closing(self.get_conn()) as conn:
  File "/home/airflow/.local/lib/python3.7/site-packages/airflow/providers/postgres/hooks/postgres.py", line 115, in get_conn
    self.conn = psycopg2.connect(**conn_args)
  File "/home/airflow/.local/lib/python3.7/site-packages/psycopg2/__init__.py", line 122, in connect
    conn = _connect(dsn, connection_factory=connection_factory, **kwasync)
psycopg2.OperationalError: connection to server at "localhost" (127.0.0.1), port 5432 failed: Connection refused
	Is the server running on that host and accepting TCP/IP connections?
connection to server at "localhost" (::1), port 5432 failed: Cannot assign requested address
	Is the server running on that host and accepting TCP/IP connections?

[2023-11-02T10:55:35.083+0000] {taskinstance.py:1406} INFO - Marking task as FAILED. dag_id=test_dag_tutorial, task_id=create_postgres_table, execution_date=20200130T000000, start_date=20231102T105533, end_date=20231102T105535
[2023-11-02T10:55:35.142+0000] {standard_task_runner.py:105} ERROR - Failed to execute job 244 for task create_postgres_table (connection to server at "localhost" (127.0.0.1), port 5432 failed: Connection refused
	Is the server running on that host and accepting TCP/IP connections?
connection to server at "localhost" (::1), port 5432 failed: Cannot assign requested address
	Is the server running on that host and accepting TCP/IP connections?
; 1458)
[2023-11-02T10:55:35.162+0000] {local_task_job.py:164} INFO - Task exited with return code 1
[2023-11-02T10:55:35.274+0000] {local_task_job.py:273} INFO - 0 downstream tasks scheduled from follow-on schedule check
[2023-11-02T10:59:30.286+0000] {taskinstance.py:1165} INFO - Dependencies all met for <TaskInstance: test_dag_tutorial.create_postgres_table scheduled__2020-01-30T00:00:00+00:00 [queued]>
[2023-11-02T10:59:30.365+0000] {taskinstance.py:1165} INFO - Dependencies all met for <TaskInstance: test_dag_tutorial.create_postgres_table scheduled__2020-01-30T00:00:00+00:00 [queued]>
[2023-11-02T10:59:30.367+0000] {taskinstance.py:1362} INFO - 
--------------------------------------------------------------------------------
[2023-11-02T10:59:30.385+0000] {taskinstance.py:1363} INFO - Starting attempt 1 of 1
[2023-11-02T10:59:30.418+0000] {taskinstance.py:1364} INFO - 
--------------------------------------------------------------------------------
[2023-11-02T10:59:30.577+0000] {taskinstance.py:1383} INFO - Executing <Task(PostgresOperator): create_postgres_table> on 2020-01-30 00:00:00+00:00
[2023-11-02T10:59:30.610+0000] {standard_task_runner.py:55} INFO - Started process 1843 to run task
[2023-11-02T10:59:30.618+0000] {standard_task_runner.py:82} INFO - Running: ['***', 'tasks', 'run', 'test_dag_tutorial', 'create_postgres_table', 'scheduled__2020-01-30T00:00:00+00:00', '--job-id', '353', '--raw', '--subdir', 'DAGS_FOLDER/test_dag_tutorial.py', '--cfg-path', '/tmp/tmpo4rp1ycz']
[2023-11-02T10:59:30.627+0000] {standard_task_runner.py:83} INFO - Job 353: Subtask create_postgres_table
[2023-11-02T10:59:31.228+0000] {task_command.py:376} INFO - Running <TaskInstance: test_dag_tutorial.create_postgres_table scheduled__2020-01-30T00:00:00+00:00 [running]> on host 1dfdc0df4852
[2023-11-02T10:59:31.654+0000] {taskinstance.py:1592} INFO - Exporting the following env vars:
AIRFLOW_CTX_DAG_OWNER=tetiana
AIRFLOW_CTX_DAG_ID=test_dag_tutorial
AIRFLOW_CTX_TASK_ID=create_postgres_table
AIRFLOW_CTX_EXECUTION_DATE=2020-01-30T00:00:00+00:00
AIRFLOW_CTX_TRY_NUMBER=1
AIRFLOW_CTX_DAG_RUN_ID=scheduled__2020-01-30T00:00:00+00:00
[2023-11-02T10:59:31.683+0000] {base.py:71} INFO - Using connection ID 'postgres_localhost' for task execution.
[2023-11-02T10:59:31.750+0000] {taskinstance.py:1851} ERROR - Task failed with exception
Traceback (most recent call last):
  File "/home/airflow/.local/lib/python3.7/site-packages/airflow/providers/postgres/operators/postgres.py", line 94, in execute
    self.hook.run(self.sql, self.autocommit, parameters=self.parameters)
  File "/home/airflow/.local/lib/python3.7/site-packages/airflow/providers/common/sql/hooks/sql.py", line 288, in run
    with closing(self.get_conn()) as conn:
  File "/home/airflow/.local/lib/python3.7/site-packages/airflow/providers/postgres/hooks/postgres.py", line 115, in get_conn
    self.conn = psycopg2.connect(**conn_args)
  File "/home/airflow/.local/lib/python3.7/site-packages/psycopg2/__init__.py", line 122, in connect
    conn = _connect(dsn, connection_factory=connection_factory, **kwasync)
psycopg2.OperationalError: connection to server at "host.docker.internal" (192.168.65.254), port 5432 failed: Connection refused
	Is the server running on that host and accepting TCP/IP connections?

[2023-11-02T10:59:31.850+0000] {taskinstance.py:1406} INFO - Marking task as FAILED. dag_id=test_dag_tutorial, task_id=create_postgres_table, execution_date=20200130T000000, start_date=20231102T105930, end_date=20231102T105931
[2023-11-02T10:59:31.937+0000] {standard_task_runner.py:105} ERROR - Failed to execute job 353 for task create_postgres_table (connection to server at "host.docker.internal" (192.168.65.254), port 5432 failed: Connection refused
	Is the server running on that host and accepting TCP/IP connections?
; 1843)
[2023-11-02T10:59:31.977+0000] {local_task_job.py:164} INFO - Task exited with return code 1
[2023-11-02T10:59:32.041+0000] {local_task_job.py:273} INFO - 0 downstream tasks scheduled from follow-on schedule check
