[2023-11-05T14:07:41.311+0000] {taskinstance.py:1165} INFO - Dependencies all met for <TaskInstance: customers.save_customers_to_excel manual__2023-11-05T14:07:35.487010+00:00 [queued]>
[2023-11-05T14:07:41.326+0000] {taskinstance.py:1165} INFO - Dependencies all met for <TaskInstance: customers.save_customers_to_excel manual__2023-11-05T14:07:35.487010+00:00 [queued]>
[2023-11-05T14:07:41.327+0000] {taskinstance.py:1362} INFO - 
--------------------------------------------------------------------------------
[2023-11-05T14:07:41.328+0000] {taskinstance.py:1363} INFO - Starting attempt 1 of 1
[2023-11-05T14:07:41.328+0000] {taskinstance.py:1364} INFO - 
--------------------------------------------------------------------------------
[2023-11-05T14:07:41.346+0000] {taskinstance.py:1383} INFO - Executing <Task(PythonOperator): save_customers_to_excel> on 2023-11-05 14:07:35.487010+00:00
[2023-11-05T14:07:41.353+0000] {standard_task_runner.py:55} INFO - Started process 11365 to run task
[2023-11-05T14:07:41.355+0000] {standard_task_runner.py:82} INFO - Running: ['***', 'tasks', 'run', 'customers', 'save_customers_to_excel', 'manual__2023-11-05T14:07:35.487010+00:00', '--job-id', '404', '--raw', '--subdir', 'DAGS_FOLDER/customers.py', '--cfg-path', '/tmp/tmpee5xy3em']
[2023-11-05T14:07:41.357+0000] {standard_task_runner.py:83} INFO - Job 404: Subtask save_customers_to_excel
[2023-11-05T14:07:41.427+0000] {task_command.py:376} INFO - Running <TaskInstance: customers.save_customers_to_excel manual__2023-11-05T14:07:35.487010+00:00 [running]> on host 9d85c6014d6e
[2023-11-05T14:07:41.516+0000] {taskinstance.py:1592} INFO - Exporting the following env vars:
AIRFLOW_CTX_DAG_OWNER=***
AIRFLOW_CTX_DAG_ID=customers
AIRFLOW_CTX_TASK_ID=save_customers_to_excel
AIRFLOW_CTX_EXECUTION_DATE=2023-11-05T14:07:35.487010+00:00
AIRFLOW_CTX_TRY_NUMBER=1
AIRFLOW_CTX_DAG_RUN_ID=manual__2023-11-05T14:07:35.487010+00:00
[2023-11-05T14:07:41.528+0000] {base.py:71} INFO - Using connection ID 'postgres' for task execution.
[2023-11-05T14:07:41.955+0000] {taskinstance.py:1851} ERROR - Task failed with exception
Traceback (most recent call last):
  File "/home/airflow/.local/lib/python3.7/site-packages/airflow/operators/python.py", line 175, in execute
    return_value = self.execute_callable()
  File "/home/airflow/.local/lib/python3.7/site-packages/airflow/operators/python.py", line 193, in execute_callable
    return self.python_callable(*self.op_args, **self.op_kwargs)
  File "/opt/airflow/dags/customers.py", line 61, in _save_customers_to_excel
    with pandas.ExcelWriter(customers_file, engine='openpyxl', mode='a') as writer:
  File "/home/airflow/.local/lib/python3.7/site-packages/pandas/io/excel/_openpyxl.py", line 57, in __init__
    engine_kwargs=engine_kwargs,
  File "/home/airflow/.local/lib/python3.7/site-packages/pandas/io/excel/_base.py", line 926, in __init__
    path, mode, storage_options=storage_options, is_text=False
  File "/home/airflow/.local/lib/python3.7/site-packages/pandas/io/common.py", line 711, in get_handle
    handle = open(handle, ioargs.mode)
PermissionError: [Errno 13] Permission denied: '/opt/data/customers.xlsx'
[2023-11-05T14:07:41.973+0000] {taskinstance.py:1406} INFO - Marking task as FAILED. dag_id=customers, task_id=save_customers_to_excel, execution_date=20231105T140735, start_date=20231105T140741, end_date=20231105T140741
[2023-11-05T14:07:41.994+0000] {standard_task_runner.py:105} ERROR - Failed to execute job 404 for task save_customers_to_excel ([Errno 13] Permission denied: '/opt/data/customers.xlsx'; 11365)
[2023-11-05T14:07:42.050+0000] {local_task_job.py:164} INFO - Task exited with return code 1
[2023-11-05T14:07:42.074+0000] {local_task_job.py:273} INFO - 0 downstream tasks scheduled from follow-on schedule check
