[2023-11-02T10:05:11.133+0000] {taskinstance.py:1165} INFO - Dependencies all met for <TaskInstance: test_dag_tutorial.create_postgres_table scheduled__2020-01-16T00:00:00+00:00 [queued]>
[2023-11-02T10:05:11.167+0000] {taskinstance.py:1165} INFO - Dependencies all met for <TaskInstance: test_dag_tutorial.create_postgres_table scheduled__2020-01-16T00:00:00+00:00 [queued]>
[2023-11-02T10:05:11.170+0000] {taskinstance.py:1362} INFO - 
--------------------------------------------------------------------------------
[2023-11-02T10:05:11.173+0000] {taskinstance.py:1363} INFO - Starting attempt 1 of 6
[2023-11-02T10:05:11.176+0000] {taskinstance.py:1364} INFO - 
--------------------------------------------------------------------------------
[2023-11-02T10:05:11.225+0000] {taskinstance.py:1383} INFO - Executing <Task(PostgresOperator): create_postgres_table> on 2020-01-16 00:00:00+00:00
[2023-11-02T10:05:11.232+0000] {standard_task_runner.py:55} INFO - Started process 901 to run task
[2023-11-02T10:05:11.248+0000] {standard_task_runner.py:82} INFO - Running: ['***', 'tasks', 'run', 'test_dag_tutorial', 'create_postgres_table', 'scheduled__2020-01-16T00:00:00+00:00', '--job-id', '65', '--raw', '--subdir', 'DAGS_FOLDER/test_dag_tutorial.py', '--cfg-path', '/tmp/tmplksje59k']
[2023-11-02T10:05:11.249+0000] {standard_task_runner.py:83} INFO - Job 65: Subtask create_postgres_table
[2023-11-02T10:05:11.349+0000] {task_command.py:376} INFO - Running <TaskInstance: test_dag_tutorial.create_postgres_table scheduled__2020-01-16T00:00:00+00:00 [running]> on host b33dd0bd4b35
[2023-11-02T10:05:11.503+0000] {taskinstance.py:1592} INFO - Exporting the following env vars:
AIRFLOW_CTX_DAG_OWNER=tetiana
AIRFLOW_CTX_DAG_ID=test_dag_tutorial
AIRFLOW_CTX_TASK_ID=create_postgres_table
AIRFLOW_CTX_EXECUTION_DATE=2020-01-16T00:00:00+00:00
AIRFLOW_CTX_TRY_NUMBER=1
AIRFLOW_CTX_DAG_RUN_ID=scheduled__2020-01-16T00:00:00+00:00
[2023-11-02T10:05:11.520+0000] {base.py:71} INFO - Using connection ID 'postgres_localhost' for task execution.
[2023-11-02T10:05:11.526+0000] {taskinstance.py:1851} ERROR - Task failed with exception
Traceback (most recent call last):
  File "/home/airflow/.local/lib/python3.7/site-packages/airflow/providers/postgres/operators/postgres.py", line 94, in execute
    self.hook.run(self.sql, self.autocommit, parameters=self.parameters)
  File "/home/airflow/.local/lib/python3.7/site-packages/airflow/providers/common/sql/hooks/sql.py", line 288, in run
    with closing(self.get_conn()) as conn:
  File "/home/airflow/.local/lib/python3.7/site-packages/airflow/providers/postgres/hooks/postgres.py", line 115, in get_conn
    self.conn = psycopg2.connect(**conn_args)
  File "/home/airflow/.local/lib/python3.7/site-packages/psycopg2/__init__.py", line 122, in connect
    conn = _connect(dsn, connection_factory=connection_factory, **kwasync)
psycopg2.OperationalError: connection to server at "host.docker.internal" (192.168.65.254), port 5432 failed: Connection refused
	Is the server running on that host and accepting TCP/IP connections?

[2023-11-02T10:05:11.544+0000] {taskinstance.py:1406} INFO - Marking task as UP_FOR_RETRY. dag_id=test_dag_tutorial, task_id=create_postgres_table, execution_date=20200116T000000, start_date=20231102T100511, end_date=20231102T100511
[2023-11-02T10:05:11.559+0000] {standard_task_runner.py:105} ERROR - Failed to execute job 65 for task create_postgres_table (connection to server at "host.docker.internal" (192.168.65.254), port 5432 failed: Connection refused
	Is the server running on that host and accepting TCP/IP connections?
; 901)
[2023-11-02T10:05:11.593+0000] {local_task_job.py:164} INFO - Task exited with return code 1
[2023-11-02T10:05:11.616+0000] {local_task_job.py:273} INFO - 0 downstream tasks scheduled from follow-on schedule check
[2023-11-02T10:46:25.900+0000] {taskinstance.py:1165} INFO - Dependencies all met for <TaskInstance: test_dag_tutorial.create_postgres_table scheduled__2020-01-16T00:00:00+00:00 [queued]>
[2023-11-02T10:46:25.920+0000] {taskinstance.py:1165} INFO - Dependencies all met for <TaskInstance: test_dag_tutorial.create_postgres_table scheduled__2020-01-16T00:00:00+00:00 [queued]>
[2023-11-02T10:46:25.922+0000] {taskinstance.py:1362} INFO - 
--------------------------------------------------------------------------------
[2023-11-02T10:46:25.923+0000] {taskinstance.py:1363} INFO - Starting attempt 1 of 6
[2023-11-02T10:46:25.923+0000] {taskinstance.py:1364} INFO - 
--------------------------------------------------------------------------------
[2023-11-02T10:46:26.018+0000] {taskinstance.py:1383} INFO - Executing <Task(PostgresOperator): create_postgres_table> on 2020-01-16 00:00:00+00:00
[2023-11-02T10:46:26.024+0000] {standard_task_runner.py:55} INFO - Started process 961 to run task
[2023-11-02T10:46:26.039+0000] {standard_task_runner.py:82} INFO - Running: ['***', 'tasks', 'run', 'test_dag_tutorial', 'create_postgres_table', 'scheduled__2020-01-16T00:00:00+00:00', '--job-id', '197', '--raw', '--subdir', 'DAGS_FOLDER/test_dag_tutorial.py', '--cfg-path', '/tmp/tmpr7xtklql']
[2023-11-02T10:46:26.047+0000] {standard_task_runner.py:83} INFO - Job 197: Subtask create_postgres_table
[2023-11-02T10:46:26.189+0000] {task_command.py:376} INFO - Running <TaskInstance: test_dag_tutorial.create_postgres_table scheduled__2020-01-16T00:00:00+00:00 [running]> on host 1dfdc0df4852
[2023-11-02T10:46:26.449+0000] {taskinstance.py:1592} INFO - Exporting the following env vars:
AIRFLOW_CTX_DAG_OWNER=tetiana
AIRFLOW_CTX_DAG_ID=test_dag_tutorial
AIRFLOW_CTX_TASK_ID=create_postgres_table
AIRFLOW_CTX_EXECUTION_DATE=2020-01-16T00:00:00+00:00
AIRFLOW_CTX_TRY_NUMBER=1
AIRFLOW_CTX_DAG_RUN_ID=scheduled__2020-01-16T00:00:00+00:00
[2023-11-02T10:46:26.487+0000] {base.py:71} INFO - Using connection ID 'postgres_localhost' for task execution.
[2023-11-02T10:46:26.489+0000] {taskinstance.py:1851} ERROR - Task failed with exception
Traceback (most recent call last):
  File "/home/airflow/.local/lib/python3.7/site-packages/airflow/providers/postgres/operators/postgres.py", line 94, in execute
    self.hook.run(self.sql, self.autocommit, parameters=self.parameters)
  File "/home/airflow/.local/lib/python3.7/site-packages/airflow/providers/common/sql/hooks/sql.py", line 288, in run
    with closing(self.get_conn()) as conn:
  File "/home/airflow/.local/lib/python3.7/site-packages/airflow/providers/postgres/hooks/postgres.py", line 115, in get_conn
    self.conn = psycopg2.connect(**conn_args)
  File "/home/airflow/.local/lib/python3.7/site-packages/psycopg2/__init__.py", line 122, in connect
    conn = _connect(dsn, connection_factory=connection_factory, **kwasync)
psycopg2.OperationalError: connection to server at "localhost" (127.0.0.1), port 5432 failed: Connection refused
	Is the server running on that host and accepting TCP/IP connections?
connection to server at "localhost" (::1), port 5432 failed: Cannot assign requested address
	Is the server running on that host and accepting TCP/IP connections?

[2023-11-02T10:46:26.511+0000] {taskinstance.py:1406} INFO - Marking task as UP_FOR_RETRY. dag_id=test_dag_tutorial, task_id=create_postgres_table, execution_date=20200116T000000, start_date=20231102T104625, end_date=20231102T104626
[2023-11-02T10:46:26.553+0000] {standard_task_runner.py:105} ERROR - Failed to execute job 197 for task create_postgres_table (connection to server at "localhost" (127.0.0.1), port 5432 failed: Connection refused
	Is the server running on that host and accepting TCP/IP connections?
connection to server at "localhost" (::1), port 5432 failed: Cannot assign requested address
	Is the server running on that host and accepting TCP/IP connections?
; 961)
[2023-11-02T10:46:26.618+0000] {local_task_job.py:164} INFO - Task exited with return code 1
[2023-11-02T10:46:26.678+0000] {local_task_job.py:273} INFO - 0 downstream tasks scheduled from follow-on schedule check
