[2023-11-05T10:07:04.626+0000] {taskinstance.py:1165} INFO - Dependencies all met for <TaskInstance: people.save_people_to_excel manual__2023-11-05T10:06:59.106490+00:00 [queued]>
[2023-11-05T10:07:04.640+0000] {taskinstance.py:1165} INFO - Dependencies all met for <TaskInstance: people.save_people_to_excel manual__2023-11-05T10:06:59.106490+00:00 [queued]>
[2023-11-05T10:07:04.641+0000] {taskinstance.py:1362} INFO - 
--------------------------------------------------------------------------------
[2023-11-05T10:07:04.641+0000] {taskinstance.py:1363} INFO - Starting attempt 1 of 1
[2023-11-05T10:07:04.642+0000] {taskinstance.py:1364} INFO - 
--------------------------------------------------------------------------------
[2023-11-05T10:07:04.661+0000] {taskinstance.py:1383} INFO - Executing <Task(PythonOperator): save_people_to_excel> on 2023-11-05 10:06:59.106490+00:00
[2023-11-05T10:07:04.667+0000] {standard_task_runner.py:55} INFO - Started process 835 to run task
[2023-11-05T10:07:04.671+0000] {standard_task_runner.py:82} INFO - Running: ['***', 'tasks', 'run', 'people', 'save_people_to_excel', 'manual__2023-11-05T10:06:59.106490+00:00', '--job-id', '232', '--raw', '--subdir', 'DAGS_FOLDER/people.py', '--cfg-path', '/tmp/tmpid9zz9vh']
[2023-11-05T10:07:04.673+0000] {standard_task_runner.py:83} INFO - Job 232: Subtask save_people_to_excel
[2023-11-05T10:07:04.740+0000] {task_command.py:376} INFO - Running <TaskInstance: people.save_people_to_excel manual__2023-11-05T10:06:59.106490+00:00 [running]> on host 0ef3ea835a0e
[2023-11-05T10:07:04.821+0000] {taskinstance.py:1592} INFO - Exporting the following env vars:
AIRFLOW_CTX_DAG_OWNER=***
AIRFLOW_CTX_DAG_ID=people
AIRFLOW_CTX_TASK_ID=save_people_to_excel
AIRFLOW_CTX_EXECUTION_DATE=2023-11-05T10:06:59.106490+00:00
AIRFLOW_CTX_TRY_NUMBER=1
AIRFLOW_CTX_DAG_RUN_ID=manual__2023-11-05T10:06:59.106490+00:00
[2023-11-05T10:07:04.831+0000] {base.py:71} INFO - Using connection ID 'postgres' for task execution.
[2023-11-05T10:07:04.844+0000] {logging_mixin.py:120} INFO - we got some sql results back!
[2023-11-05T10:07:04.870+0000] {logging_mixin.py:120} INFO -     index          user_id  ... date_of_birth              job_title
0       1  88F7B33d2bcf9f5  ...    1945-10-26        Games developer
1       2  f90cD3E76f1A9b9  ...    1910-03-24         Phytotherapist
2       3  DbeAb8CcdfeFC2c  ...    1992-07-02              Homeopath
3       4  A31Bee3c201ef58  ...    2017-08-03      Market researcher
4       5  1bA7A3dc874da3c  ...    1938-12-01     Veterinary surgeon
..    ...              ...  ...           ...                    ...
95     96  5eFda7caAeB260E  ...    1954-07-30      Software engineer
96     97  CCbFce93d3720bE  ...    1932-04-29              Barrister
97     98  2fEc528aFAF0b69  ...    1994-12-28         Police officer
98     99  Adc7ad9B6e4A1Fe  ...    2012-04-12   Broadcast journalist
99    100  b8D0aD3490FC7e1  ...    2016-11-15  IT sales professional

[100 rows x 9 columns]
[2023-11-05T10:07:04.873+0000] {taskinstance.py:1851} ERROR - Task failed with exception
Traceback (most recent call last):
  File "/home/airflow/.local/lib/python3.7/site-packages/airflow/operators/python.py", line 175, in execute
    return_value = self.execute_callable()
  File "/home/airflow/.local/lib/python3.7/site-packages/airflow/operators/python.py", line 193, in execute_callable
    return self.python_callable(*self.op_args, **self.op_kwargs)
  File "/opt/airflow/dags/people.py", line 71, in _save_people_to_excel
    df.to_excel(countries_file, sheet_name='Test')
  File "/home/airflow/.local/lib/python3.7/site-packages/pandas/core/generic.py", line 2291, in to_excel
    storage_options=storage_options,
  File "/home/airflow/.local/lib/python3.7/site-packages/pandas/io/formats/excel.py", line 835, in write
    writer, engine=engine, storage_options=storage_options
  File "/home/airflow/.local/lib/python3.7/site-packages/pandas/io/excel/_openpyxl.py", line 48, in __init__
    from openpyxl.workbook import Workbook
ModuleNotFoundError: No module named 'openpyxl'
[2023-11-05T10:07:04.891+0000] {taskinstance.py:1406} INFO - Marking task as FAILED. dag_id=people, task_id=save_people_to_excel, execution_date=20231105T100659, start_date=20231105T100704, end_date=20231105T100704
[2023-11-05T10:07:04.908+0000] {standard_task_runner.py:105} ERROR - Failed to execute job 232 for task save_people_to_excel (No module named 'openpyxl'; 835)
[2023-11-05T10:07:04.923+0000] {local_task_job.py:164} INFO - Task exited with return code 1
[2023-11-05T10:07:04.945+0000] {local_task_job.py:273} INFO - 0 downstream tasks scheduled from follow-on schedule check
