[2023-11-02T10:05:11.109+0000] {taskinstance.py:1165} INFO - Dependencies all met for <TaskInstance: test_dag_tutorial.create_postgres_table scheduled__2020-01-15T00:00:00+00:00 [queued]>
[2023-11-02T10:05:11.132+0000] {taskinstance.py:1165} INFO - Dependencies all met for <TaskInstance: test_dag_tutorial.create_postgres_table scheduled__2020-01-15T00:00:00+00:00 [queued]>
[2023-11-02T10:05:11.133+0000] {taskinstance.py:1362} INFO - 
--------------------------------------------------------------------------------
[2023-11-02T10:05:11.145+0000] {taskinstance.py:1363} INFO - Starting attempt 1 of 6
[2023-11-02T10:05:11.146+0000] {taskinstance.py:1364} INFO - 
--------------------------------------------------------------------------------
[2023-11-02T10:05:11.195+0000] {taskinstance.py:1383} INFO - Executing <Task(PostgresOperator): create_postgres_table> on 2020-01-15 00:00:00+00:00
[2023-11-02T10:05:11.203+0000] {standard_task_runner.py:55} INFO - Started process 900 to run task
[2023-11-02T10:05:11.209+0000] {standard_task_runner.py:82} INFO - Running: ['***', 'tasks', 'run', 'test_dag_tutorial', 'create_postgres_table', 'scheduled__2020-01-15T00:00:00+00:00', '--job-id', '64', '--raw', '--subdir', 'DAGS_FOLDER/test_dag_tutorial.py', '--cfg-path', '/tmp/tmpvmczft3k']
[2023-11-02T10:05:11.210+0000] {standard_task_runner.py:83} INFO - Job 64: Subtask create_postgres_table
[2023-11-02T10:05:11.338+0000] {task_command.py:376} INFO - Running <TaskInstance: test_dag_tutorial.create_postgres_table scheduled__2020-01-15T00:00:00+00:00 [running]> on host b33dd0bd4b35
[2023-11-02T10:05:11.509+0000] {taskinstance.py:1592} INFO - Exporting the following env vars:
AIRFLOW_CTX_DAG_OWNER=tetiana
AIRFLOW_CTX_DAG_ID=test_dag_tutorial
AIRFLOW_CTX_TASK_ID=create_postgres_table
AIRFLOW_CTX_EXECUTION_DATE=2020-01-15T00:00:00+00:00
AIRFLOW_CTX_TRY_NUMBER=1
AIRFLOW_CTX_DAG_RUN_ID=scheduled__2020-01-15T00:00:00+00:00
[2023-11-02T10:05:11.524+0000] {base.py:71} INFO - Using connection ID 'postgres_localhost' for task execution.
[2023-11-02T10:05:11.530+0000] {taskinstance.py:1851} ERROR - Task failed with exception
Traceback (most recent call last):
  File "/home/airflow/.local/lib/python3.7/site-packages/airflow/providers/postgres/operators/postgres.py", line 94, in execute
    self.hook.run(self.sql, self.autocommit, parameters=self.parameters)
  File "/home/airflow/.local/lib/python3.7/site-packages/airflow/providers/common/sql/hooks/sql.py", line 288, in run
    with closing(self.get_conn()) as conn:
  File "/home/airflow/.local/lib/python3.7/site-packages/airflow/providers/postgres/hooks/postgres.py", line 115, in get_conn
    self.conn = psycopg2.connect(**conn_args)
  File "/home/airflow/.local/lib/python3.7/site-packages/psycopg2/__init__.py", line 122, in connect
    conn = _connect(dsn, connection_factory=connection_factory, **kwasync)
psycopg2.OperationalError: connection to server at "host.docker.internal" (192.168.65.254), port 5432 failed: Connection refused
	Is the server running on that host and accepting TCP/IP connections?

[2023-11-02T10:05:11.546+0000] {taskinstance.py:1406} INFO - Marking task as UP_FOR_RETRY. dag_id=test_dag_tutorial, task_id=create_postgres_table, execution_date=20200115T000000, start_date=20231102T100511, end_date=20231102T100511
[2023-11-02T10:05:11.567+0000] {standard_task_runner.py:105} ERROR - Failed to execute job 64 for task create_postgres_table (connection to server at "host.docker.internal" (192.168.65.254), port 5432 failed: Connection refused
	Is the server running on that host and accepting TCP/IP connections?
; 900)
[2023-11-02T10:05:11.594+0000] {local_task_job.py:164} INFO - Task exited with return code 1
[2023-11-02T10:05:11.624+0000] {local_task_job.py:273} INFO - 0 downstream tasks scheduled from follow-on schedule check
[2023-11-02T10:37:15.156+0000] {taskinstance.py:1165} INFO - Dependencies all met for <TaskInstance: test_dag_tutorial.create_postgres_table scheduled__2020-01-15T00:00:00+00:00 [queued]>
[2023-11-02T10:37:15.179+0000] {taskinstance.py:1165} INFO - Dependencies all met for <TaskInstance: test_dag_tutorial.create_postgres_table scheduled__2020-01-15T00:00:00+00:00 [queued]>
[2023-11-02T10:37:15.180+0000] {taskinstance.py:1362} INFO - 
--------------------------------------------------------------------------------
[2023-11-02T10:37:15.180+0000] {taskinstance.py:1363} INFO - Starting attempt 1 of 6
[2023-11-02T10:37:15.181+0000] {taskinstance.py:1364} INFO - 
--------------------------------------------------------------------------------
[2023-11-02T10:37:15.210+0000] {taskinstance.py:1383} INFO - Executing <Task(PostgresOperator): create_postgres_table> on 2020-01-15 00:00:00+00:00
[2023-11-02T10:37:15.215+0000] {standard_task_runner.py:55} INFO - Started process 509 to run task
[2023-11-02T10:37:15.219+0000] {standard_task_runner.py:82} INFO - Running: ['***', 'tasks', 'run', 'test_dag_tutorial', 'create_postgres_table', 'scheduled__2020-01-15T00:00:00+00:00', '--job-id', '180', '--raw', '--subdir', 'DAGS_FOLDER/test_dag_tutorial.py', '--cfg-path', '/tmp/tmp7r_v9rop']
[2023-11-02T10:37:15.220+0000] {standard_task_runner.py:83} INFO - Job 180: Subtask create_postgres_table
[2023-11-02T10:37:15.290+0000] {task_command.py:376} INFO - Running <TaskInstance: test_dag_tutorial.create_postgres_table scheduled__2020-01-15T00:00:00+00:00 [running]> on host 1dfdc0df4852
[2023-11-02T10:37:15.412+0000] {taskinstance.py:1592} INFO - Exporting the following env vars:
AIRFLOW_CTX_DAG_OWNER=tetiana
AIRFLOW_CTX_DAG_ID=test_dag_tutorial
AIRFLOW_CTX_TASK_ID=create_postgres_table
AIRFLOW_CTX_EXECUTION_DATE=2020-01-15T00:00:00+00:00
AIRFLOW_CTX_TRY_NUMBER=1
AIRFLOW_CTX_DAG_RUN_ID=scheduled__2020-01-15T00:00:00+00:00
[2023-11-02T10:37:15.423+0000] {base.py:71} INFO - Using connection ID 'postgres_localhost' for task execution.
[2023-11-02T10:37:15.426+0000] {taskinstance.py:1851} ERROR - Task failed with exception
Traceback (most recent call last):
  File "/home/airflow/.local/lib/python3.7/site-packages/airflow/providers/postgres/operators/postgres.py", line 94, in execute
    self.hook.run(self.sql, self.autocommit, parameters=self.parameters)
  File "/home/airflow/.local/lib/python3.7/site-packages/airflow/providers/common/sql/hooks/sql.py", line 288, in run
    with closing(self.get_conn()) as conn:
  File "/home/airflow/.local/lib/python3.7/site-packages/airflow/providers/postgres/hooks/postgres.py", line 115, in get_conn
    self.conn = psycopg2.connect(**conn_args)
  File "/home/airflow/.local/lib/python3.7/site-packages/psycopg2/__init__.py", line 122, in connect
    conn = _connect(dsn, connection_factory=connection_factory, **kwasync)
psycopg2.OperationalError: connection to server at "localhost" (127.0.0.1), port 5432 failed: Connection refused
	Is the server running on that host and accepting TCP/IP connections?
connection to server at "localhost" (::1), port 5432 failed: Cannot assign requested address
	Is the server running on that host and accepting TCP/IP connections?

[2023-11-02T10:37:15.437+0000] {taskinstance.py:1406} INFO - Marking task as UP_FOR_RETRY. dag_id=test_dag_tutorial, task_id=create_postgres_table, execution_date=20200115T000000, start_date=20231102T103715, end_date=20231102T103715
[2023-11-02T10:37:15.463+0000] {standard_task_runner.py:105} ERROR - Failed to execute job 180 for task create_postgres_table (connection to server at "localhost" (127.0.0.1), port 5432 failed: Connection refused
	Is the server running on that host and accepting TCP/IP connections?
connection to server at "localhost" (::1), port 5432 failed: Cannot assign requested address
	Is the server running on that host and accepting TCP/IP connections?
; 509)
[2023-11-02T10:37:15.519+0000] {local_task_job.py:164} INFO - Task exited with return code 1
[2023-11-02T10:37:15.629+0000] {local_task_job.py:273} INFO - 0 downstream tasks scheduled from follow-on schedule check
[2023-11-02T10:46:10.756+0000] {taskinstance.py:1165} INFO - Dependencies all met for <TaskInstance: test_dag_tutorial.create_postgres_table scheduled__2020-01-15T00:00:00+00:00 [queued]>
[2023-11-02T10:46:10.794+0000] {taskinstance.py:1165} INFO - Dependencies all met for <TaskInstance: test_dag_tutorial.create_postgres_table scheduled__2020-01-15T00:00:00+00:00 [queued]>
[2023-11-02T10:46:10.795+0000] {taskinstance.py:1362} INFO - 
--------------------------------------------------------------------------------
[2023-11-02T10:46:10.797+0000] {taskinstance.py:1363} INFO - Starting attempt 1 of 6
[2023-11-02T10:46:10.798+0000] {taskinstance.py:1364} INFO - 
--------------------------------------------------------------------------------
[2023-11-02T10:46:10.925+0000] {taskinstance.py:1383} INFO - Executing <Task(PostgresOperator): create_postgres_table> on 2020-01-15 00:00:00+00:00
[2023-11-02T10:46:10.934+0000] {standard_task_runner.py:55} INFO - Started process 938 to run task
[2023-11-02T10:46:10.963+0000] {standard_task_runner.py:82} INFO - Running: ['***', 'tasks', 'run', 'test_dag_tutorial', 'create_postgres_table', 'scheduled__2020-01-15T00:00:00+00:00', '--job-id', '190', '--raw', '--subdir', 'DAGS_FOLDER/test_dag_tutorial.py', '--cfg-path', '/tmp/tmpjblhk713']
[2023-11-02T10:46:10.979+0000] {standard_task_runner.py:83} INFO - Job 190: Subtask create_postgres_table
[2023-11-02T10:46:11.350+0000] {task_command.py:376} INFO - Running <TaskInstance: test_dag_tutorial.create_postgres_table scheduled__2020-01-15T00:00:00+00:00 [running]> on host 1dfdc0df4852
[2023-11-02T10:46:12.431+0000] {taskinstance.py:1592} INFO - Exporting the following env vars:
AIRFLOW_CTX_DAG_OWNER=tetiana
AIRFLOW_CTX_DAG_ID=test_dag_tutorial
AIRFLOW_CTX_TASK_ID=create_postgres_table
AIRFLOW_CTX_EXECUTION_DATE=2020-01-15T00:00:00+00:00
AIRFLOW_CTX_TRY_NUMBER=1
AIRFLOW_CTX_DAG_RUN_ID=scheduled__2020-01-15T00:00:00+00:00
[2023-11-02T10:46:12.543+0000] {base.py:71} INFO - Using connection ID 'postgres_localhost' for task execution.
[2023-11-02T10:46:12.546+0000] {taskinstance.py:1851} ERROR - Task failed with exception
Traceback (most recent call last):
  File "/home/airflow/.local/lib/python3.7/site-packages/airflow/providers/postgres/operators/postgres.py", line 94, in execute
    self.hook.run(self.sql, self.autocommit, parameters=self.parameters)
  File "/home/airflow/.local/lib/python3.7/site-packages/airflow/providers/common/sql/hooks/sql.py", line 288, in run
    with closing(self.get_conn()) as conn:
  File "/home/airflow/.local/lib/python3.7/site-packages/airflow/providers/postgres/hooks/postgres.py", line 115, in get_conn
    self.conn = psycopg2.connect(**conn_args)
  File "/home/airflow/.local/lib/python3.7/site-packages/psycopg2/__init__.py", line 122, in connect
    conn = _connect(dsn, connection_factory=connection_factory, **kwasync)
psycopg2.OperationalError: connection to server at "localhost" (127.0.0.1), port 5432 failed: Connection refused
	Is the server running on that host and accepting TCP/IP connections?
connection to server at "localhost" (::1), port 5432 failed: Cannot assign requested address
	Is the server running on that host and accepting TCP/IP connections?

[2023-11-02T10:46:12.587+0000] {taskinstance.py:1406} INFO - Marking task as UP_FOR_RETRY. dag_id=test_dag_tutorial, task_id=create_postgres_table, execution_date=20200115T000000, start_date=20231102T104610, end_date=20231102T104612
[2023-11-02T10:46:12.772+0000] {standard_task_runner.py:105} ERROR - Failed to execute job 190 for task create_postgres_table (connection to server at "localhost" (127.0.0.1), port 5432 failed: Connection refused
	Is the server running on that host and accepting TCP/IP connections?
connection to server at "localhost" (::1), port 5432 failed: Cannot assign requested address
	Is the server running on that host and accepting TCP/IP connections?
; 938)
[2023-11-02T10:46:12.806+0000] {local_task_job.py:164} INFO - Task exited with return code 1
[2023-11-02T10:46:12.856+0000] {local_task_job.py:273} INFO - 0 downstream tasks scheduled from follow-on schedule check
