[2023-11-02T20:55:52.415+0000] {taskinstance.py:1165} INFO - Dependencies all met for <TaskInstance: read_csv_dag.read_csv_task manual__2023-11-02T20:53:11.598104+00:00 [queued]>
[2023-11-02T20:55:52.432+0000] {taskinstance.py:1165} INFO - Dependencies all met for <TaskInstance: read_csv_dag.read_csv_task manual__2023-11-02T20:53:11.598104+00:00 [queued]>
[2023-11-02T20:55:52.433+0000] {taskinstance.py:1362} INFO - 
--------------------------------------------------------------------------------
[2023-11-02T20:55:52.436+0000] {taskinstance.py:1363} INFO - Starting attempt 4 of 4
[2023-11-02T20:55:52.437+0000] {taskinstance.py:1364} INFO - 
--------------------------------------------------------------------------------
[2023-11-02T20:55:52.463+0000] {taskinstance.py:1383} INFO - Executing <Task(PythonOperator): read_csv_task> on 2023-11-02 20:53:11.598104+00:00
[2023-11-02T20:55:52.474+0000] {standard_task_runner.py:55} INFO - Started process 6180 to run task
[2023-11-02T20:55:52.480+0000] {standard_task_runner.py:82} INFO - Running: ['***', 'tasks', 'run', 'read_csv_dag', 'read_csv_task', 'manual__2023-11-02T20:53:11.598104+00:00', '--job-id', '43', '--raw', '--subdir', 'DAGS_FOLDER/people.py', '--cfg-path', '/tmp/tmpyuwxugv2']
[2023-11-02T20:55:52.481+0000] {standard_task_runner.py:83} INFO - Job 43: Subtask read_csv_task
[2023-11-02T20:55:52.561+0000] {task_command.py:376} INFO - Running <TaskInstance: read_csv_dag.read_csv_task manual__2023-11-02T20:53:11.598104+00:00 [running]> on host 6c8be2bfe956
[2023-11-02T20:55:52.665+0000] {taskinstance.py:1592} INFO - Exporting the following env vars:
AIRFLOW_CTX_DAG_OWNER=***
AIRFLOW_CTX_DAG_ID=read_csv_dag
AIRFLOW_CTX_TASK_ID=read_csv_task
AIRFLOW_CTX_EXECUTION_DATE=2023-11-02T20:53:11.598104+00:00
AIRFLOW_CTX_TRY_NUMBER=4
AIRFLOW_CTX_DAG_RUN_ID=manual__2023-11-02T20:53:11.598104+00:00
[2023-11-02T20:55:52.674+0000] {taskinstance.py:1851} ERROR - Task failed with exception
Traceback (most recent call last):
  File "/home/airflow/.local/lib/python3.7/site-packages/airflow/operators/python.py", line 175, in execute
    return_value = self.execute_callable()
  File "/home/airflow/.local/lib/python3.7/site-packages/airflow/operators/python.py", line 193, in execute_callable
    return self.python_callable(*self.op_args, **self.op_kwargs)
  File "/opt/airflow/dags/people.py", line 14, in read_csv_file
    print(row['Index'],row['User Id'], row['First Name'], row['Last Name'], row['Sex'], row['Email'], row['Phone'], row['Date of birth'], row['Job Title'])
KeyError: 'User Id'
[2023-11-02T20:55:52.690+0000] {taskinstance.py:1406} INFO - Marking task as FAILED. dag_id=read_csv_dag, task_id=read_csv_task, execution_date=20231102T205311, start_date=20231102T205552, end_date=20231102T205552
[2023-11-02T20:55:52.708+0000] {standard_task_runner.py:105} ERROR - Failed to execute job 43 for task read_csv_task ('User Id'; 6180)
[2023-11-02T20:55:52.770+0000] {local_task_job.py:164} INFO - Task exited with return code 1
[2023-11-02T20:55:52.796+0000] {local_task_job.py:273} INFO - 0 downstream tasks scheduled from follow-on schedule check
