[2023-11-04T20:45:10.113+0000] {taskinstance.py:1165} INFO - Dependencies all met for <TaskInstance: people.read_people manual__2023-11-04T20:45:07.188498+00:00 [queued]>
[2023-11-04T20:45:10.127+0000] {taskinstance.py:1165} INFO - Dependencies all met for <TaskInstance: people.read_people manual__2023-11-04T20:45:07.188498+00:00 [queued]>
[2023-11-04T20:45:10.128+0000] {taskinstance.py:1362} INFO - 
--------------------------------------------------------------------------------
[2023-11-04T20:45:10.129+0000] {taskinstance.py:1363} INFO - Starting attempt 1 of 1
[2023-11-04T20:45:10.129+0000] {taskinstance.py:1364} INFO - 
--------------------------------------------------------------------------------
[2023-11-04T20:45:10.149+0000] {taskinstance.py:1383} INFO - Executing <Task(PythonOperator): read_people> on 2023-11-04 20:45:07.188498+00:00
[2023-11-04T20:45:10.156+0000] {standard_task_runner.py:55} INFO - Started process 3629 to run task
[2023-11-04T20:45:10.159+0000] {standard_task_runner.py:82} INFO - Running: ['***', 'tasks', 'run', 'people', 'read_people', 'manual__2023-11-04T20:45:07.188498+00:00', '--job-id', '221', '--raw', '--subdir', 'DAGS_FOLDER/people.py', '--cfg-path', '/tmp/tmpdebxxq68']
[2023-11-04T20:45:10.160+0000] {standard_task_runner.py:83} INFO - Job 221: Subtask read_people
[2023-11-04T20:45:10.239+0000] {task_command.py:376} INFO - Running <TaskInstance: people.read_people manual__2023-11-04T20:45:07.188498+00:00 [running]> on host 0ef3ea835a0e
[2023-11-04T20:45:10.335+0000] {taskinstance.py:1592} INFO - Exporting the following env vars:
AIRFLOW_CTX_DAG_OWNER=***
AIRFLOW_CTX_DAG_ID=people
AIRFLOW_CTX_TASK_ID=read_people
AIRFLOW_CTX_EXECUTION_DATE=2023-11-04T20:45:07.188498+00:00
AIRFLOW_CTX_TRY_NUMBER=1
AIRFLOW_CTX_DAG_RUN_ID=manual__2023-11-04T20:45:07.188498+00:00
[2023-11-04T20:45:10.350+0000] {taskinstance.py:1851} ERROR - Task failed with exception
Traceback (most recent call last):
  File "/home/airflow/.local/lib/python3.7/site-packages/airflow/operators/python.py", line 175, in execute
    return_value = self.execute_callable()
  File "/home/airflow/.local/lib/python3.7/site-packages/airflow/operators/python.py", line 193, in execute_callable
    return self.python_callable(*self.op_args, **self.op_kwargs)
  File "/opt/airflow/dags/people.py", line 35, in _read_people
    row[1].strip(),
IndexError: list index out of range
[2023-11-04T20:45:10.363+0000] {taskinstance.py:1406} INFO - Marking task as FAILED. dag_id=people, task_id=read_people, execution_date=20231104T204507, start_date=20231104T204510, end_date=20231104T204510
[2023-11-04T20:45:10.379+0000] {standard_task_runner.py:105} ERROR - Failed to execute job 221 for task read_people (list index out of range; 3629)
[2023-11-04T20:45:10.413+0000] {local_task_job.py:164} INFO - Task exited with return code 1
[2023-11-04T20:45:10.438+0000] {local_task_job.py:273} INFO - 0 downstream tasks scheduled from follow-on schedule check
