[2023-11-05T10:53:32.977+0000] {taskinstance.py:1165} INFO - Dependencies all met for <TaskInstance: people.save_people_to_excel manual__2023-11-05T10:53:28.330930+00:00 [queued]>
[2023-11-05T10:53:32.993+0000] {taskinstance.py:1165} INFO - Dependencies all met for <TaskInstance: people.save_people_to_excel manual__2023-11-05T10:53:28.330930+00:00 [queued]>
[2023-11-05T10:53:32.993+0000] {taskinstance.py:1362} INFO - 
--------------------------------------------------------------------------------
[2023-11-05T10:53:32.994+0000] {taskinstance.py:1363} INFO - Starting attempt 1 of 1
[2023-11-05T10:53:32.995+0000] {taskinstance.py:1364} INFO - 
--------------------------------------------------------------------------------
[2023-11-05T10:53:33.014+0000] {taskinstance.py:1383} INFO - Executing <Task(PythonOperator): save_people_to_excel> on 2023-11-05 10:53:28.330930+00:00
[2023-11-05T10:53:33.021+0000] {standard_task_runner.py:55} INFO - Started process 2056 to run task
[2023-11-05T10:53:33.024+0000] {standard_task_runner.py:82} INFO - Running: ['***', 'tasks', 'run', 'people', 'save_people_to_excel', 'manual__2023-11-05T10:53:28.330930+00:00', '--job-id', '278', '--raw', '--subdir', 'DAGS_FOLDER/people.py', '--cfg-path', '/tmp/tmp8trdf57w']
[2023-11-05T10:53:33.026+0000] {standard_task_runner.py:83} INFO - Job 278: Subtask save_people_to_excel
[2023-11-05T10:53:33.122+0000] {task_command.py:376} INFO - Running <TaskInstance: people.save_people_to_excel manual__2023-11-05T10:53:28.330930+00:00 [running]> on host 9d85c6014d6e
[2023-11-05T10:53:33.207+0000] {taskinstance.py:1592} INFO - Exporting the following env vars:
AIRFLOW_CTX_DAG_OWNER=***
AIRFLOW_CTX_DAG_ID=people
AIRFLOW_CTX_TASK_ID=save_people_to_excel
AIRFLOW_CTX_EXECUTION_DATE=2023-11-05T10:53:28.330930+00:00
AIRFLOW_CTX_TRY_NUMBER=1
AIRFLOW_CTX_DAG_RUN_ID=manual__2023-11-05T10:53:28.330930+00:00
[2023-11-05T10:53:33.218+0000] {base.py:71} INFO - Using connection ID 'postgres' for task execution.
[2023-11-05T10:53:33.223+0000] {taskinstance.py:1851} ERROR - Task failed with exception
Traceback (most recent call last):
  File "/home/airflow/.local/lib/python3.7/site-packages/pandas/io/sql.py", line 2056, in execute
    cur.execute(*args, **kwargs)
psycopg2.errors.InvalidColumnReference: SELECT DISTINCT ON expressions must match initial ORDER BY expressions
LINE 1: SELECT DISTINCT ON (user_id)  * FROM people ORDER BY index A...
                            ^


The above exception was the direct cause of the following exception:

Traceback (most recent call last):
  File "/home/airflow/.local/lib/python3.7/site-packages/airflow/operators/python.py", line 175, in execute
    return_value = self.execute_callable()
  File "/home/airflow/.local/lib/python3.7/site-packages/airflow/operators/python.py", line 193, in execute_callable
    return self.python_callable(*self.op_args, **self.op_kwargs)
  File "/opt/airflow/dags/people.py", line 52, in _save_people_to_excel
    df = hook.get_pandas_df(sql="SELECT DISTINCT ON (user_id)  * FROM people ORDER BY index ASC")
  File "/home/airflow/.local/lib/python3.7/site-packages/airflow/providers/common/sql/hooks/sql.py", line 176, in get_pandas_df
    return psql.read_sql(sql, con=conn, params=parameters, **kwargs)
  File "/home/airflow/.local/lib/python3.7/site-packages/pandas/io/sql.py", line 608, in read_sql
    chunksize=chunksize,
  File "/home/airflow/.local/lib/python3.7/site-packages/pandas/io/sql.py", line 2116, in read_query
    cursor = self.execute(*args)
  File "/home/airflow/.local/lib/python3.7/site-packages/pandas/io/sql.py", line 2068, in execute
    raise ex from exc
pandas.io.sql.DatabaseError: Execution failed on sql 'SELECT DISTINCT ON (user_id)  * FROM people ORDER BY index ASC': SELECT DISTINCT ON expressions must match initial ORDER BY expressions
LINE 1: SELECT DISTINCT ON (user_id)  * FROM people ORDER BY index A...
                            ^

[2023-11-05T10:53:33.237+0000] {taskinstance.py:1406} INFO - Marking task as FAILED. dag_id=people, task_id=save_people_to_excel, execution_date=20231105T105328, start_date=20231105T105332, end_date=20231105T105333
[2023-11-05T10:53:33.251+0000] {standard_task_runner.py:105} ERROR - Failed to execute job 278 for task save_people_to_excel (Execution failed on sql 'SELECT DISTINCT ON (user_id)  * FROM people ORDER BY index ASC': SELECT DISTINCT ON expressions must match initial ORDER BY expressions
LINE 1: SELECT DISTINCT ON (user_id)  * FROM people ORDER BY index A...
                            ^
; 2056)
[2023-11-05T10:53:33.277+0000] {local_task_job.py:164} INFO - Task exited with return code 1
[2023-11-05T10:53:33.299+0000] {local_task_job.py:273} INFO - 0 downstream tasks scheduled from follow-on schedule check
