[2023-11-01T20:08:40.605+0000] {taskinstance.py:1165} INFO - Dependencies all met for <TaskInstance: xcom_dag.branch manual__2023-11-01T20:08:38.013780+00:00 [queued]>
[2023-11-01T20:08:40.618+0000] {taskinstance.py:1165} INFO - Dependencies all met for <TaskInstance: xcom_dag.branch manual__2023-11-01T20:08:38.013780+00:00 [queued]>
[2023-11-01T20:08:40.619+0000] {taskinstance.py:1362} INFO - 
--------------------------------------------------------------------------------
[2023-11-01T20:08:40.619+0000] {taskinstance.py:1363} INFO - Starting attempt 1 of 1
[2023-11-01T20:08:40.620+0000] {taskinstance.py:1364} INFO - 
--------------------------------------------------------------------------------
[2023-11-01T20:08:40.642+0000] {taskinstance.py:1383} INFO - Executing <Task(BranchPythonOperator): branch> on 2023-11-01 20:08:38.013780+00:00
[2023-11-01T20:08:40.648+0000] {standard_task_runner.py:55} INFO - Started process 2137 to run task
[2023-11-01T20:08:40.651+0000] {standard_task_runner.py:82} INFO - Running: ['***', 'tasks', 'run', 'xcom_dag', 'branch', 'manual__2023-11-01T20:08:38.013780+00:00', '--job-id', '26', '--raw', '--subdir', 'DAGS_FOLDER/xcom_dag.py', '--cfg-path', '/tmp/tmpd1d55zzj']
[2023-11-01T20:08:40.652+0000] {standard_task_runner.py:83} INFO - Job 26: Subtask branch
[2023-11-01T20:08:40.721+0000] {task_command.py:376} INFO - Running <TaskInstance: xcom_dag.branch manual__2023-11-01T20:08:38.013780+00:00 [running]> on host 3779655fe886
[2023-11-01T20:08:40.811+0000] {taskinstance.py:1592} INFO - Exporting the following env vars:
AIRFLOW_CTX_DAG_OWNER=***
AIRFLOW_CTX_DAG_ID=xcom_dag
AIRFLOW_CTX_TASK_ID=branch
AIRFLOW_CTX_EXECUTION_DATE=2023-11-01T20:08:38.013780+00:00
AIRFLOW_CTX_TRY_NUMBER=1
AIRFLOW_CTX_DAG_RUN_ID=manual__2023-11-01T20:08:38.013780+00:00
[2023-11-01T20:08:40.812+0000] {taskinstance.py:1851} ERROR - Task failed with exception
Traceback (most recent call last):
  File "/home/airflow/.local/lib/python3.7/site-packages/airflow/operators/python.py", line 211, in execute
    branch = super().execute(context)
  File "/home/airflow/.local/lib/python3.7/site-packages/airflow/operators/python.py", line 175, in execute
    return_value = self.execute_callable()
  File "/home/airflow/.local/lib/python3.7/site-packages/airflow/operators/python.py", line 193, in execute_callable
    return self.python_callable(*self.op_args, **self.op_kwargs)
  File "/opt/airflow/dags/xcom_dag.py", line 14, in _branch
    value = ti.xcom_pull(key='my_key', task_id='t1')
  File "/home/airflow/.local/lib/python3.7/site-packages/airflow/utils/session.py", line 75, in wrapper
    return func(*args, session=session, **kwargs)
TypeError: xcom_pull() got an unexpected keyword argument 'task_id'
[2023-11-01T20:08:40.825+0000] {taskinstance.py:1406} INFO - Marking task as FAILED. dag_id=xcom_dag, task_id=branch, execution_date=20231101T200838, start_date=20231101T200840, end_date=20231101T200840
[2023-11-01T20:08:40.839+0000] {standard_task_runner.py:105} ERROR - Failed to execute job 26 for task branch (xcom_pull() got an unexpected keyword argument 'task_id'; 2137)
[2023-11-01T20:08:40.863+0000] {local_task_job.py:164} INFO - Task exited with return code 1
[2023-11-01T20:08:40.911+0000] {local_task_job.py:273} INFO - 0 downstream tasks scheduled from follow-on schedule check
