[2023-11-05T15:54:33.340+0000] {taskinstance.py:1165} INFO - Dependencies all met for <TaskInstance: customers.save_customers_to_excel manual__2023-11-05T15:54:26.650212+00:00 [queued]>
[2023-11-05T15:54:33.353+0000] {taskinstance.py:1165} INFO - Dependencies all met for <TaskInstance: customers.save_customers_to_excel manual__2023-11-05T15:54:26.650212+00:00 [queued]>
[2023-11-05T15:54:33.354+0000] {taskinstance.py:1362} INFO - 
--------------------------------------------------------------------------------
[2023-11-05T15:54:33.355+0000] {taskinstance.py:1363} INFO - Starting attempt 1 of 1
[2023-11-05T15:54:33.355+0000] {taskinstance.py:1364} INFO - 
--------------------------------------------------------------------------------
[2023-11-05T15:54:33.375+0000] {taskinstance.py:1383} INFO - Executing <Task(PythonOperator): save_customers_to_excel> on 2023-11-05 15:54:26.650212+00:00
[2023-11-05T15:54:33.382+0000] {standard_task_runner.py:55} INFO - Started process 16400 to run task
[2023-11-05T15:54:33.385+0000] {standard_task_runner.py:82} INFO - Running: ['***', 'tasks', 'run', 'customers', 'save_customers_to_excel', 'manual__2023-11-05T15:54:26.650212+00:00', '--job-id', '443', '--raw', '--subdir', 'DAGS_FOLDER/customers.py', '--cfg-path', '/tmp/tmpg24f_xsa']
[2023-11-05T15:54:33.387+0000] {standard_task_runner.py:83} INFO - Job 443: Subtask save_customers_to_excel
[2023-11-05T15:54:33.463+0000] {task_command.py:376} INFO - Running <TaskInstance: customers.save_customers_to_excel manual__2023-11-05T15:54:26.650212+00:00 [running]> on host 9d85c6014d6e
[2023-11-05T15:54:33.711+0000] {taskinstance.py:1592} INFO - Exporting the following env vars:
AIRFLOW_CTX_DAG_OWNER=***
AIRFLOW_CTX_DAG_ID=customers
AIRFLOW_CTX_TASK_ID=save_customers_to_excel
AIRFLOW_CTX_EXECUTION_DATE=2023-11-05T15:54:26.650212+00:00
AIRFLOW_CTX_TRY_NUMBER=1
AIRFLOW_CTX_DAG_RUN_ID=manual__2023-11-05T15:54:26.650212+00:00
[2023-11-05T15:54:33.713+0000] {taskinstance.py:1851} ERROR - Task failed with exception
Traceback (most recent call last):
  File "/home/airflow/.local/lib/python3.7/site-packages/airflow/operators/python.py", line 175, in execute
    return_value = self.execute_callable()
  File "/home/airflow/.local/lib/python3.7/site-packages/airflow/operators/python.py", line 193, in execute_callable
    return self.python_callable(*self.op_args, **self.op_kwargs)
  File "/opt/airflow/dags/customers.py", line 61, in _save_customers_to_excel
    wb = openpyxl.load_workbook(customers_file)
  File "/home/airflow/.local/lib/python3.7/site-packages/openpyxl/reader/excel.py", line 345, in load_workbook
    data_only, keep_links, rich_text)
  File "/home/airflow/.local/lib/python3.7/site-packages/openpyxl/reader/excel.py", line 123, in __init__
    self.archive = _validate_archive(fn)
  File "/home/airflow/.local/lib/python3.7/site-packages/openpyxl/reader/excel.py", line 95, in _validate_archive
    archive = ZipFile(filename, 'r')
  File "/usr/local/lib/python3.7/zipfile.py", line 1240, in __init__
    self.fp = io.open(file, filemode)
FileNotFoundError: [Errno 2] No such file or directory: '/opt/data/customers.xlsx'
[2023-11-05T15:54:33.728+0000] {taskinstance.py:1406} INFO - Marking task as FAILED. dag_id=customers, task_id=save_customers_to_excel, execution_date=20231105T155426, start_date=20231105T155433, end_date=20231105T155433
[2023-11-05T15:54:33.742+0000] {standard_task_runner.py:105} ERROR - Failed to execute job 443 for task save_customers_to_excel ([Errno 2] No such file or directory: '/opt/data/customers.xlsx'; 16400)
[2023-11-05T15:54:33.758+0000] {local_task_job.py:164} INFO - Task exited with return code 1
[2023-11-05T15:54:33.782+0000] {local_task_job.py:273} INFO - 0 downstream tasks scheduled from follow-on schedule check
