[2023-11-01T20:09:35.200+0000] {taskinstance.py:1165} INFO - Dependencies all met for <TaskInstance: xcom_dag.branch manual__2023-11-01T20:09:32.548439+00:00 [queued]>
[2023-11-01T20:09:35.214+0000] {taskinstance.py:1165} INFO - Dependencies all met for <TaskInstance: xcom_dag.branch manual__2023-11-01T20:09:32.548439+00:00 [queued]>
[2023-11-01T20:09:35.215+0000] {taskinstance.py:1362} INFO - 
--------------------------------------------------------------------------------
[2023-11-01T20:09:35.216+0000] {taskinstance.py:1363} INFO - Starting attempt 1 of 1
[2023-11-01T20:09:35.217+0000] {taskinstance.py:1364} INFO - 
--------------------------------------------------------------------------------
[2023-11-01T20:09:35.245+0000] {taskinstance.py:1383} INFO - Executing <Task(BranchPythonOperator): branch> on 2023-11-01 20:09:32.548439+00:00
[2023-11-01T20:09:35.251+0000] {standard_task_runner.py:55} INFO - Started process 2187 to run task
[2023-11-01T20:09:35.254+0000] {standard_task_runner.py:82} INFO - Running: ['***', 'tasks', 'run', 'xcom_dag', 'branch', 'manual__2023-11-01T20:09:32.548439+00:00', '--job-id', '28', '--raw', '--subdir', 'DAGS_FOLDER/xcom_dag.py', '--cfg-path', '/tmp/tmpi8ma6oi_']
[2023-11-01T20:09:35.255+0000] {standard_task_runner.py:83} INFO - Job 28: Subtask branch
[2023-11-01T20:09:35.329+0000] {task_command.py:376} INFO - Running <TaskInstance: xcom_dag.branch manual__2023-11-01T20:09:32.548439+00:00 [running]> on host 3779655fe886
[2023-11-01T20:09:35.420+0000] {taskinstance.py:1592} INFO - Exporting the following env vars:
AIRFLOW_CTX_DAG_OWNER=***
AIRFLOW_CTX_DAG_ID=xcom_dag
AIRFLOW_CTX_TASK_ID=branch
AIRFLOW_CTX_EXECUTION_DATE=2023-11-01T20:09:32.548439+00:00
AIRFLOW_CTX_TRY_NUMBER=1
AIRFLOW_CTX_DAG_RUN_ID=manual__2023-11-01T20:09:32.548439+00:00
[2023-11-01T20:09:35.421+0000] {taskinstance.py:1851} ERROR - Task failed with exception
Traceback (most recent call last):
  File "/home/airflow/.local/lib/python3.7/site-packages/airflow/operators/python.py", line 211, in execute
    branch = super().execute(context)
  File "/home/airflow/.local/lib/python3.7/site-packages/airflow/operators/python.py", line 175, in execute
    return_value = self.execute_callable()
  File "/home/airflow/.local/lib/python3.7/site-packages/airflow/operators/python.py", line 193, in execute_callable
    return self.python_callable(*self.op_args, **self.op_kwargs)
  File "/opt/airflow/dags/xcom_dag.py", line 14, in _branch
    value = ti.xcom_pull(key='my_key', task_id='t1')
  File "/home/airflow/.local/lib/python3.7/site-packages/airflow/utils/session.py", line 75, in wrapper
    return func(*args, session=session, **kwargs)
TypeError: xcom_pull() got an unexpected keyword argument 'task_id'
[2023-11-01T20:09:35.434+0000] {taskinstance.py:1406} INFO - Marking task as FAILED. dag_id=xcom_dag, task_id=branch, execution_date=20231101T200932, start_date=20231101T200935, end_date=20231101T200935
[2023-11-01T20:09:35.458+0000] {standard_task_runner.py:105} ERROR - Failed to execute job 28 for task branch (xcom_pull() got an unexpected keyword argument 'task_id'; 2187)
[2023-11-01T20:09:35.507+0000] {local_task_job.py:164} INFO - Task exited with return code 1
[2023-11-01T20:09:35.569+0000] {local_task_job.py:273} INFO - 0 downstream tasks scheduled from follow-on schedule check
