[2023-11-04T20:33:15.581+0000] {taskinstance.py:1165} INFO - Dependencies all met for <TaskInstance: people.read_people manual__2023-11-04T20:33:11.189357+00:00 [queued]>
[2023-11-04T20:33:15.596+0000] {taskinstance.py:1165} INFO - Dependencies all met for <TaskInstance: people.read_people manual__2023-11-04T20:33:11.189357+00:00 [queued]>
[2023-11-04T20:33:15.597+0000] {taskinstance.py:1362} INFO - 
--------------------------------------------------------------------------------
[2023-11-04T20:33:15.598+0000] {taskinstance.py:1363} INFO - Starting attempt 1 of 1
[2023-11-04T20:33:15.599+0000] {taskinstance.py:1364} INFO - 
--------------------------------------------------------------------------------
[2023-11-04T20:33:15.621+0000] {taskinstance.py:1383} INFO - Executing <Task(PythonOperator): read_people> on 2023-11-04 20:33:11.189357+00:00
[2023-11-04T20:33:15.628+0000] {standard_task_runner.py:55} INFO - Started process 3032 to run task
[2023-11-04T20:33:15.631+0000] {standard_task_runner.py:82} INFO - Running: ['***', 'tasks', 'run', 'people', 'read_people', 'manual__2023-11-04T20:33:11.189357+00:00', '--job-id', '207', '--raw', '--subdir', 'DAGS_FOLDER/people.py', '--cfg-path', '/tmp/tmpo6dbimhy']
[2023-11-04T20:33:15.632+0000] {standard_task_runner.py:83} INFO - Job 207: Subtask read_people
[2023-11-04T20:33:15.699+0000] {task_command.py:376} INFO - Running <TaskInstance: people.read_people manual__2023-11-04T20:33:11.189357+00:00 [running]> on host 0ef3ea835a0e
[2023-11-04T20:33:15.787+0000] {taskinstance.py:1592} INFO - Exporting the following env vars:
AIRFLOW_CTX_DAG_OWNER=***
AIRFLOW_CTX_DAG_ID=people
AIRFLOW_CTX_TASK_ID=read_people
AIRFLOW_CTX_EXECUTION_DATE=2023-11-04T20:33:11.189357+00:00
AIRFLOW_CTX_TRY_NUMBER=1
AIRFLOW_CTX_DAG_RUN_ID=manual__2023-11-04T20:33:11.189357+00:00
[2023-11-04T20:33:15.796+0000] {taskinstance.py:1851} ERROR - Task failed with exception
Traceback (most recent call last):
  File "/home/airflow/.local/lib/python3.7/site-packages/airflow/operators/python.py", line 175, in execute
    return_value = self.execute_callable()
  File "/home/airflow/.local/lib/python3.7/site-packages/airflow/operators/python.py", line 193, in execute_callable
    return self.python_callable(*self.op_args, **self.op_kwargs)
  File "/opt/airflow/dags/people.py", line 29, in _read_people
    index,
UnboundLocalError: local variable 'index' referenced before assignment
[2023-11-04T20:33:15.811+0000] {taskinstance.py:1406} INFO - Marking task as FAILED. dag_id=people, task_id=read_people, execution_date=20231104T203311, start_date=20231104T203315, end_date=20231104T203315
[2023-11-04T20:33:15.824+0000] {standard_task_runner.py:105} ERROR - Failed to execute job 207 for task read_people (local variable 'index' referenced before assignment; 3032)
[2023-11-04T20:33:15.843+0000] {local_task_job.py:164} INFO - Task exited with return code 1
[2023-11-04T20:33:15.865+0000] {local_task_job.py:273} INFO - 0 downstream tasks scheduled from follow-on schedule check
